<?xml version="1.0"?>
<robot xmlns:xacro="http://www.ros.org/wiki/xacro" name="Assembly">

	<material name="silver">
		<color rgba="0.700 0.700 0.700 1.000" />
	</material>

	<xacro:include filename="colours.xacro" />

	<link name="world"></link>

	<joint name="base_joint" type="fixed">
		<origin xyz="0 0 0.0" rpy="0 0 0" />
		<parent link="world" />
		<child link="base_link" />
	</joint>

	<!-- Base link -->

	<link name="base_link">
		<inertial>
			<origin xyz="0.07534510435136411 0.041236994202469936 0.012233421118945254" rpy="0 0 0" />
			<mass value="1.509259717395697" />
			<inertia ixx="0.002025413200436247" iyy="0.01575536948738211" izz="0.017115842947411287"
				ixy="9.190668177905433e-06" iyz="-1.321879237211991e-07" ixz="0.0006849511383840069" />
		</inertial>
		<visual>
			<origin xyz="0 0 0" rpy="0 0 0" />
			<geometry>
				<mesh filename="file://$(find my_robot)/urdf/meshes/base_link.stl"
					scale="0.001 0.001 0.001" />
			</geometry>
			<material name="silver" />
			<material />
		</visual>
		<collision>
			<origin xyz="0 0 0" rpy="0 0 0" />
			<geometry>
				<mesh filename="file://$(find my_robot)/urdf/meshes/base_link.stl"
					scale="0.001 0.001 0.001" />
			</geometry>
		</collision>
	</link>

	<!-- Front left -->
	<link name="Wheel31">
		<inertial>
			<origin xyz="2.419116294227752e-07 -0.02749965116389138 -2.5590366655586783e-08"
				rpy="0 0 0" />
			<mass value="0.5775672191550701" />
			<inertia ixx="0.0006304923225381167" iyy="0.0009817859201656635"
				izz="0.0006304923225309142" ixy="8.673617379884035e-19" iyz="-3.469446951953614e-18"
				ixz="-2.0599841277224584e-18" />
		</inertial>
		<visual>
			<origin xyz="0.047313 0.062217 0.019156" rpy="0 0 0" />
			<geometry>
				<mesh filename="file://$(find my_robot)/urdf/meshes/Wheel31.stl"
					scale="0.001 0.001 0.001" />
			</geometry>
			<material name="silver" />
			<material />
		</visual>
		<collision>
			<origin xyz="0.047313 0.062217 0.019156" rpy="0 0 0" />
			<geometry>
				<mesh filename="file://$(find my_robot)/urdf/meshes/Wheel31.stl"
					scale="0.001 0.001 0.001" />
			</geometry>
		</collision>
	</link>

	<joint name="Front_left" type="continuous">
		<origin xyz="-0.047313 -0.062217 -0.019156" rpy="0 0 0" />
		<parent link="base_link" />
		<child link="Wheel31" />
		<axis xyz="-0.0 1.0 0.0" />
	</joint>
	
	<transmission name="Front_left_tran">
		<type>transmission_interface/SimpleTransmission</type>
		<joint name="Front_left">
			<hardwareInterface>PositionJointInterface</hardwareInterface>
		</joint>
		<actuator name="Front_left_actr">
			<hardwareInterface>PositionJointInterface</hardwareInterface>
			<mechanicalReduction>1</mechanicalReduction>
		</actuator>
	</transmission>

	<!-- Back left -->
	<link name="Wheel41">
		<inertial>
			<origin xyz="2.4191162950604195e-07 -0.027499651163891366 -2.55903664647672e-08"
				rpy="0 0 0" />
			<mass value="0.5775672191550701" />
			<inertia ixx="0.0006304923225381081" iyy="0.0009817859201656579"
				izz="0.0006304923225308179" ixy="-1.5612511283791264e-17"
				iyz="-4.336808689942018e-19" ixz="8.673617379884035e-19" />
		</inertial>
		<visual>
			<origin xyz="-0.252687 0.062217 0.019156" rpy="0 0 0" />
			<geometry>
				<mesh filename="file://$(find my_robot)/urdf/meshes/Wheel41.stl"
					scale="0.001 0.001 0.001" />
			</geometry>
			<material name="silver" />
			<material />
		</visual>
		<collision>
			<origin xyz="-0.252687 0.062217 0.019156" rpy="0 0 0" />
			<geometry>
				<mesh filename="file://$(find my_robot)/urdf/meshes/Wheel41.stl"
					scale="0.001 0.001 0.001" />
			</geometry>
		</collision>
	</link>

	<joint name="Rear_left" type="continuous">
		<origin xyz="0.252687 -0.062217 -0.019156" rpy="0 0 0" />
		<parent link="base_link" />
		<child link="Wheel41" />
		<axis xyz="-0.0 1.0 0.0" />
	</joint>

	<transmission name="Rear_left_tran">
		<type>transmission_interface/SimpleTransmission</type>
		<joint name="Rear_left">
			<hardwareInterface>PositionJointInterface</hardwareInterface>
		</joint>
		<actuator name="Rear_left_actr">
			<hardwareInterface>PositionJointInterface</hardwareInterface>
			<mechanicalReduction>1</mechanicalReduction>
		</actuator>
	</transmission>

	<!-- Back right -->
	<link name="Wheel21">
		<inertial>
			<origin xyz="2.419116293395085e-07 0.027500348836108995 -2.559036639537826e-08"
				rpy="0 0 0" />
			<mass value="0.5775672191550697" />
			<inertia ixx="0.0006304923225379858" iyy="0.000981785920165415"
				izz="0.000630492322531026" ixy="-6.591949208711867e-17" iyz="1.0842021724855044e-17"
				ixz="8.673617379884035e-18" />
		</inertial>
		<visual>
			<origin xyz="-0.252687 -0.144783 0.019156" rpy="0 0 0" />
			<geometry>
				<mesh filename="file://$(find my_robot)/urdf/meshes/Wheel21.stl"
					scale="0.001 0.001 0.001" />
			</geometry>
			<material name="silver" />
			<material />
		</visual>
		<collision>
			<origin xyz="-0.252687 -0.144783 0.019156" rpy="0 0 0" />
			<geometry>
				<mesh filename="file://$(find my_robot)/urdf/meshes/Wheel21.stl"
					scale="0.001 0.001 0.001" />
			</geometry>
		</collision>
	</link>

	<joint name="Rear_right" type="continuous">
		<origin xyz="0.252687 0.144783 -0.019156" rpy="0 0 0" />
		<parent link="base_link" />
		<child link="Wheel21" />
		<axis xyz="0.0 -1.0 -0.0" />
	</joint>

	<transmission name="Rear_right_tran">
		<type>transmission_interface/SimpleTransmission</type>
		<joint name="Rear_right">
			<hardwareInterface>PositionJointInterface</hardwareInterface>
		</joint>
		<actuator name="Rear_right_actr">
			<hardwareInterface>PositionJointInterface</hardwareInterface>
			<mechanicalReduction>1</mechanicalReduction>
		</actuator>
	</transmission>

	<!-- Front right -->
	<link name="Wheel11">
		<inertial>
			<origin xyz="2.4191162938808075e-07 0.027500348836108718 -2.5590366593136737e-08"
				rpy="0 0 0" />
			<mass value="0.5775672191550699" />
			<inertia ixx="0.0006304923225378747" iyy="0.0009817859201654295"
				izz="0.0006304923225309185" ixy="-3.469446951953614e-18"
				iyz="4.7704895589362195e-18" ixz="1.1926223897340549e-18" />
		</inertial>
		<visual>
			<origin xyz="0.047313 -0.144783 0.019156" rpy="0 0 0" />
			<geometry>
				<mesh filename="file://$(find my_robot)/urdf/meshes/Wheel11.stl"
					scale="0.001 0.001 0.001" />
			</geometry>
			<material name="silver" />
			<material />
		</visual>
		<collision>
			<origin xyz="0.047313 -0.144783 0.019156" rpy="0 0 0" />
			<geometry>
				<mesh filename="file://$(find my_robot)/urdf/meshes/Wheel11.stl"
					scale="0.001 0.001 0.001" />
			</geometry>
		</collision>
	</link>





	<joint name="Front_right" type="continuous">
		<origin xyz="-0.047313 0.144783 -0.019156" rpy="0 0 0" />
		<parent link="base_link" />
		<child link="Wheel11" />
		<axis xyz="0.0 -1.0 -0.0" />
	</joint>
	<transmission name="Front_right_tran">
		<type>transmission_interface/SimpleTransmission</type>
		<joint name="Front_right">
			<hardwareInterface>PositionJointInterface</hardwareInterface>
		</joint>
		<actuator name="Front_right_actr">
			<hardwareInterface>PositionJointInterface</hardwareInterface>
			<mechanicalReduction>1</mechanicalReduction>
		</actuator>
	</transmission>

</robot>