<?xml version="1.0" ?>
<!-- =================================================================================== -->
<!-- |    This document was autogenerated by xacro from mobile_robot.urdf.xacro        | -->
<!-- |    EDITING THIS FILE BY HAND IS NOT RECOMMENDED                                 | -->
<!-- =================================================================================== -->
<robot name="mobile_robot">
  <link name="robot_body">
    <visual>
      <!-- rpy is for roll pitch yaw which are the euler angles that specify orientation-->
      <origin rpy="0 0 0" xyz="0 0 0"/>
      <geometry>
        <!-- size of the body, which is a box -->
        <box size="1 0.6 0.3"/>
      </geometry>
      <material name="red">
        <color rgba="1 0 0 1"/>
      </material>
    </visual>
    <collision>
      <origin rpy="0 0 0" xyz="0 0 0"/>
      <geometry>
        <box size="1 0.6 0.3"/>
      </geometry>
    </collision>
    <!-- using the mass of the chasis as 1.0 kg and constructing the moment of inertia tensor based on a solid cuboid-->
    <inertial>
      <mass value="1.0"/>
      <!-- specify upper triangle -->
      <inertia ixx="0.0375" ixy="0" ixz="0" iyy="0.113333333" iyz="0" izz="0.0908333333"/>
    </inertial>
  </link>
  <link name="wheel_left_upper_link">
    <visual>
      <!-- origin of the coordinate system attached to the centre of mass 
            is rotated 1.570795 radiants around the roll axis (x axis).
            Means that the cylinder defining the wheel is rotated around the x-axis
            to place the cylinder in the correct position.-->
      <origin rpy="1.570795 0 0" xyz="0 0 0"/>
      <geometry>
        <!--The wheel is a cylinder with radius of 0.15 and with the length of 0.1.-->
        <cylinder length="0.1" radius="0.15"/>
      </geometry>
      <material name="yellow">
        <color rgba="1 1 0 1"/>
      </material>
    </visual>
    <collision>
      <origin rpy="1.570795 0 0" xyz="0 0 0"/>
      <geometry>
        <cylinder length="0.1" radius="0.15"/>
      </geometry>
    </collision>
    <inertial>
      <mass value="0.1"/>
      <!-- specify upper triangle -->
      <inertia ixx="0.0006458333333333334" ixy="0" ixz="0" iyy="0.0006458333333333334" iyz="0" izz="0.001125"/>
    </inertial>
  </link>
  <!-- continuous type so that the wheel can continuously rotate with respect to the robot base. -->
  <joint name="wheel_left_upper_joint" type="continuous">
    <parent link="robot_body"/>
    <child link="wheel_left_upper_link"/>
    <origin rpy="0 0 0" xyz="0.3 0.35 -0.1"/>
    <!-- axis of rotation around y axis -->
    <axis xyz="0 1 0"/>
  </joint>
  <link name="wheel_left_lower_link">
    <visual>
  
      <origin rpy="1.570795 0 0" xyz="0 0 0"/>
      <geometry>
  
        <cylinder length="0.1" radius="0.15"/>
      </geometry>
      <material name="yellow">
        <color rgba="1 1 0 1"/>
      </material>
    </visual>
    <collision>
      <origin rpy="1.570795 0 0" xyz="0 0 0"/>
      <geometry>
        <cylinder length="0.1" radius="0.15"/>
      </geometry>
    </collision>
    <inertial>
      <mass value="0.1"/>

      <inertia ixx="0.0006458333333333334" ixy="0" ixz="0" iyy="0.0006458333333333334" iyz="0" izz="0.001125"/>
    </inertial>
  </link>

</robot>